Workbook

Sheet 1 ข้อมูล
B1: 1) ข้อมูลออกแบบ — บ่อ 3 ช่อง: ปั๊มจุ่ม | โชว์น้ำใส | V-notch 90°
B2: แก้เฉพาะช่องสีเหลือง (ตัวเลขสีน้ำเงิน) แล้วชีต 2–6 จะคำนวณขนาดและระดับใหม่ให้ทั้งหมด
B4: รายการ | C4: ค่า | D4: หน่วย | E4: ที่มา / หมายเหตุ
B5: ก. อัตราการไหล
B6: น้ำเข้าต่อวัน | C6: 1507 | D6: m³/วัน | E6: จาก whiteboard
B7: น้ำเข้าต่ำสุด | C7: 50 | D7: m³/h | E7: จากใบเสนอราคา (50–100 m³/h)
B8: น้ำเข้าสูงสุด | C8: 100 | D8: m³/h | E8: จากใบเสนอราคา (50–100 m³/h)
B9: สูบไป Water recycle | C9: 10 | D9: m³/h | E9: จาก whiteboard
B10: น้ำเข้าเฉลี่ย (= น้ำต่อวัน ÷ 24) | C10: ='1 ข้อมูล'!$C$6/24 -> 62.791667 | D10: m³/h | E10: คำนวณให้
B12: ข. เกณฑ์ออกแบบ (ค่าที่วิศวกรกำหนด แก้ได้)
B13: ปัดขนาดขึ้นทีละ | C13: 0.05 | D13: m | E13: ให้ได้ขนาดก่อสร้างลงตัว
B14: เผื่อตะกอนใต้ยอด V | C14: 0.05 | D14: m | E14: บวกเพิ่มจาก P ขั้นต่ำ เผื่อตะกอนสะสมที่พื้น
B15: ร่อง V สูงกว่า Hmax อย่างน้อย | C15: 0.08 | D15: m | E15: กันน้ำล้นขอบร่อง
B16: สันช่อง 2 สูงกว่าน้ำช่อง 3 อย่างน้อย | C16: 0.1 | D16: m | E16: ให้ม่านน้ำตกอิสระ
B17: ความสูงสันปลาย ช่อง 2 | C17: 0.02 | D17: m | E17: สูงขึ้น = ชั้นน้ำหนาขึ้น ผิวน้ำเรียบขึ้น
B18: ความยาวช่องโชว์น้ำ (ช่อง 2) | C18: 1 | D18: m | E18: เลือกตามความสวยงาม (ต้อง ≥ ค่าขั้นต่ำในชีต 3)
B19: ความกว้างบ่อขั้นต่ำที่เลือก | C19: 1.5 | D19: m | E19: เผื่อ b ≥ 2Hmax ไว้ถึงน้ำเข้า ~125 m³/h (ค่าตามเกณฑ์ 1.44)
B20: ระยะเผื่อขอบบ่อ (freeboard) | C20: 0.2 | D20: m | E20: เหนือระดับน้ำสูงสุด
B21: ความเร็วลอดใต้ผนังกั้น ไม่เกิน | C21: 0.1 | D21: m/s | E21: ช้าพอไม่ให้น้ำพุ่งต่อไปช่อง 2
B22: ขนาดภายนอกท่อจุ่ม 6" | C22: 0.168 | D22: m | E22: ท่อ 6" OD 168 mm
B23: ระยะห่างท่อจุ่มจากผนัง (ข้างละ) | C23: 0.15 | D23: m | E23: ไว้ยึดท่อ / ซ่อมบำรุง
B24: ความหนาผนังกั้นลอดใต้ | C24: 0.1 | D24: m | E24: คสล. หรือแผ่น SS/PP + โครง
... B35: ระยะเผื่อหลังม่านน้ำ V-notch | C35: 0.2 | D35: m | E35: ม่านน้ำไม่ชนผนังท้าย
B36: ขนาดภายในท่อออก 8" | C36: 0.2 | D36: m
B37: สันกำแพงเวียร์ ต่ำกว่ายอด V | C37: 0.1 | D37: m | E37: ส่วนที่เหลือเป็นแผ่น SS
B38: แผ่นเวียร์ทับกำแพง (ยึดพุก) | C38: 0.1 | D38: m
B39: แผ่นเวียร์สูงเหนือขอบร่อง V | C39: 0.1 | D39: m | E39: ให้แผ่นแข็งแรง
B40: แผ่นเวียร์ฝังร่องผนัง (ข้างละ) | C40: 0.1 | D40: m | E40: ครึ่งหนึ่งของผนัง 0.20
B41: ความหนาแผ่นเวียร์ SS304 | C41: 0.006 | D41: m
B42: BOD probe: ระยะจากต้นช่วงตรง | C42: 0.3 | D42: m | E42: ช่วงต้นของช่วงตรง พ้นโซนฟอง
B43: BOD probe: ระยะจากผนังข้าง | C43: 0.15 | D43: m | E43: ชิดผนัง ไม่ขวางกลางร่องน้ำ
B44: BOD probe: จมน้ำขั้นต่ำ | C44: 0.25 | D44: m | E44: ยืนยันกับผู้ขาย WTW
B45: BOD probe: สูงจากพื้นขั้นต่ำ | C45: 0.2 | D45: m | E45: พ้นตะกอนที่พื้น
B46: Flow meter (DL10): ระดับหน้าเซนเซอร์ | C46: 1.1 | D46: m | E46: ติดคานพาดขวางเหนือจุดวัด H
B47: Flow meter (DL10): ระยะวัดต่ำสุด (blanking) | C47: 0.05 | D47: m | E47: Badger DL10: 50–1,250 mm
B48: Flow meter (DL10): ระยะวัดสูงสุด | C48: 1.25 | D48: m
B49: ความหนาผนัง คสล. | C49: 0.2 | D49: m | E49: ขั้นต่ำที่นิยมสำหรับถังเก็บน้ำ (เหล็ก 2 ชั้น)
B50: ความหนาพื้น คสล. | C50: 0.2 | D50: m
B51: ระยะหุ้มคอนกรีต | C51: 0.05 | D51: m | E51: ผิวสัมผัสน้ำ
B53: ค. ค่าคงที่ (ไม่ต้องแก้)
...

Sheet 2 เวียร์
B1: 2) เวียร์ V-notch 90° — หาความสูงน้ำ H จากอัตราการไหล
B2: สูตรหลัก (กรมควบคุมมลพิษ): Q = 1.38 × H^2.5 → H = (Q ÷ 1.38)^0.4 | สูตรเทียบ (ISO 1438): Q = K × (H + kh)^2.5 → H = (Q ÷ K)^0.4 − kh
B4: ขั้นที่ 1 ค่าคงที่ของแต่ละสูตร
B5: สูตรกรมควบคุมมลพิษ | C5: ='1 ข้อมูล'!$C$56 -> 1.38 | D5: - | E5: ค่าคงที่ตายตัว
B6: สูตร ISO: K = Ce × (8/15) × √(2g) | C6: ='1 ข้อมูล'!$C$57*(8/15)*SQRT(2*'1 ข้อมูล'!$C$54) -> 1.3654508 | D6: - | E6: ≈ 1.365 และบวก kh ที่ H
B8: ขั้นที่ 2 แปลงอัตราการไหล แล้วหา H ทั้ง 2 สูตร
B9: กรณี | C9: Q ผ่านเวียร์ (m³/h) | D9: Q (m³/s) = ÷3600 | E9: H กรมฯ (cm) = (Q÷1.38)^0.4 | F9: H ISO (cm) = (Q÷K)^0.4 − kh | G9: ต่างกัน (cm) = กรมฯ − ISO | H9: หมายเหตุ
B10: น้ำเข้าต่ำสุด ปั๊มเดิน | C10: ='1 ข้อมูล'!$C$7-'1 ข้อมูล'!$C$9 -> 40 | D10: =C10/3600 -> 0.011111111 | E10: =(D10/'2 เวียร์'!$C$5)^0.4*100 -> 14.532869 | F10: =((D10/'2 เวียร์'!$C$6)^0.4-'1 ข้อมูล'!$C$58)*100 -> 14.509613 | G10: =E10-F10 -> 0.023256578
B11: น้ำเข้าเฉลี่ย ปั๊มเดิน | C11: ='1 ข้อมูล'!$C$10-'1 ข้อมูล'!$C$9 -> 52.791667 | D11: =C11/3600 -> 0.014664352 | E11: =(D11/'2 เวียร์'!$C$5)^0.4*100 -> 16.238784 | F11: =((D11/'2 เวียร์'!$C$6)^0.4-'1 ข้อมูล'!$C$58)*100 -> 16.222775 | G11: =E11-F11 -> 0.016008936 | H11: ใช้งานปกติ
B12: น้ำเข้าสูงสุด ปั๊มเดิน | C12: ='1 ข้อมูล'!$C$8-'1 ข้อมูล'!$C$9 -> 90 | D12: =C12/3600 -> 0.025 | E12: =(D12/'2 เวียร์'!$C$5)^0.4*100 -> 20.10131 | F12: =((D12/'2 เวียร์'!$C$6)^0.4-'1 ข้อมูล'!$C$58)*100 -> 20.101712 | G12: =E12-F12 -> -0.00040114636
B13: น้ำเข้าสูงสุด ปั๊มหยุด | C13: ='1 ข้อมูล'!$C$8 -> 100 | D13: =C13/3600 -> 0.027777778 | E13: =(D13/'2 เวียร์'!$C$5)^0.4*100 -> 20.966569 | F13: =((D13/'2 เวียร์'!$C$6)^0.4-'1 ข้อมูล'!$C$58)*100 -> 20.970646 | G13: =E13-F13 -> -0.0040772286 | H13: ← Hmax ใช้หาขนาด
B15: • ทั้ง 2 สูตรมาจาก Q = Cd × (8/15) × √(2g) × H^2.5 ต่างกันที่ Cd: กรมฯ 0.584 (→ 1.38) / ISO 0.578 (→ 1.365)
B16: • ISO บวก kh = 0.85 mm ที่ H เพื่อชดเชยแรงตึงผิวตอนน้ำตื้น จึงต่างกันมากเฉพาะ H < 10 cm
B17: • ช่วงใช้งานบ่อนี้ต่างกันไม่ถึง 0.5% — รายงานราชการให้ใช้สูตรกรมฯ

Sheet 3 ขนาดบ่อ
B1: 3) คำนวณขนาดบ่อและแผ่นเวียร์ — ทุกขนาดมาจากสูตร
B2: คอลัมน์ 'ค่าขั้นต่ำ' = ผลจากเกณฑ์ | คอลัมน์ 'ใช้' = ปัดขึ้นทีละ 0.05 m (หรือค่าที่กำหนด) | ตรวจ ✔/✘ ท้ายแต่ละหมวด
B4: รายการ | C4: วิธีคิด | D4: ค่าขั้นต่ำ | E4: ใช้ | F4: หน่วย | G4: เหตุผล / เกณฑ์
B6: ก. ขนาดเวียร์ (จาก Hmax)
B7: Hmax (ความสูงน้ำเหนือยอด V สูงสุด) | C7: จากชีต 2 กรณีปั๊มหยุด | E7: =('2 เวียร์'!$E$13/100) -> 0.20966569 | F7: m | G7: Q = 100 m³/h
B8: P ความสูงยอด V จากพื้นบ่อ | C8: MAX(0.45, H ÷ 0.4) + เผื่อตะกอน | D8: =MAX(0.45,'3 ขนาดบ่อ'!$E$7/0.4)+'1 ข้อมูล'!$C$14 -> 0.57416422 | E8: =CEILING(ROUND(D8,4),'1 ข้อมูล'!$C$13) -> 0.6 | F8: m | G8: เกณฑ์ ISO: P ≥ 0.45 m และ H/P ≤ 0.4
B9: ความลึกร่อง V | C9: H + 0.08 | D9: ='3 ขนาดบ่อ'!$E$7+'1 ข้อมูล'!$C$15 -> 0.28966569 | E9: =CEILING(ROUND(D9,4),'1 ข้อมูล'!$C$13) -> 0.3 | F9: m | G9: น้ำไม่ล้นขอบร่อง
B10: ความกว้างปากร่อง V | C10: 2 × ความลึก × tan45° | E10: =2*'3 ขนาดบ่อ'!$E$9 -> 0.6 | F10: m | G10: ร่อง 90° กว้าง = 2 เท่าของลึก
B11: b ระยะขอบร่อง V ถึงผนัง (ข้างละ) | C11: ≥ 2 × H (เกณฑ์ USBR / เอกสาร มข.) | E11: =2*'3 ขนาดบ่อ'!$E$7 -> 0.41933138 | F11: m | G11: น้ำเข้าร่องไม่ถูกผนังข้างบีบ
B12: B ตามเกณฑ์ | C12: MAX(0.90, H ÷ 0.2, ปากร่อง + 2b) | E12: =MAX(0.9,'3 ขนาดบ่อ'!$E$7/0.2,'3 ขนาดบ่อ'!$E$10+2*'3 ขนาดบ่อ'!$E$11) -> 1.4386628 | F12: m | G12: ISO: B ≥ 0.90 และ H/B ≤ 0.2 / USBR–มข.: b ≥ 2H ข้างละ
B13: B ความกว้างภายในบ่อ (ใช้) | C13: MAX(ตามเกณฑ์, ค่าที่เลือก) | D13: =MAX('3 ขนาดบ่อ'!$E$12,'1 ข้อมูล'!$C$19) -> 1.5 | E13: =CEILING(ROUND(D13,4),'1 ข้อมูล'!$C$13) -> 1.5 | F13: m | G13: เลือก 1.50 เพื่อมีระยะเผื่อ
B14: ช่วงตรงหน้าเวียร์ | C14: 10 × H | D14: =10*'3 ขนาดบ่อ'!$E$7 -> 2.0966569 | E14: =CEILING(ROUND(D14,4),'1 ข้อมูล'!$C$13) -> 2.1 | F14: m | G14: ให้ความเร็วเท่ากันทั้งหน้าตัดก่อนถึงเวียร์
B15: จุดวัด H ห่างแผ่นเวียร์ | C15: 4.5 × H (กลางช่วง 4–5 H) | D15: =4.5*'3 ขนาดบ่อ'!$E$7 -> 0.9434956 | E15: =ROUND(D15/'1 ข้อมูล'!$C$13,0)*'1 ข้อมูล'!$C$13 -> 0.95 | F15: m | G15: นอกเขตที่ผิวน้ำลดระดับเข้าหาร่อง
B16: ตรวจ: H/P | C16: ≤ 0.4 | D16: ='3 ขนาดบ่อ'!$E$7/'3 ขนาดบ่อ'!$E$8 -> 0.34944281 | E16: =IF(D16<=0.4,"ผ่าน ✔","ไม่ผ่าน ✘") -> ผ่าน ✔
B17: ตรวจ: H/B | C17: ≤ 0.2 | D17: ='3 ขนาดบ่อ'!$E$7/'3 ขนาดบ่อ'!$E$13 -> 0.13977713 | E17: =IF(D17<=0.2,"ผ่าน ✔","ไม่ผ่าน ✘") -> ผ่าน ✔
B18: ตรวจ: b จริง = (B − ปากร่อง) ÷ 2 | C18: ≥ 2H | D18: =('3 ขนาดบ่อ'!$E$13-'3 ขนาดบ่อ'!$E$10)/2 -> 0.45 | E18: =IF(D18>=2*'3 ขนาดบ่อ'!$E$7,"ผ่าน ✔","ไม่ผ่าน ✘") -> ผ่าน ✔ | G18: เกณฑ์ USBR / เอกสาร มข.
B19: น้ำเข้าสูงสุดที่ b ยังผ่าน | C19: 1.38 × (b ÷ 2)^2.5 × 3600 | E19: ='1 ข้อมูล'!$C$56*(('3 ขนาดบ่อ'!$E$13-'3 ขนาดบ่อ'!$E$10)/4)^2.5*3600 -> 119.2993 | F19: m³/h | G19: ระยะเผื่อเทียบกับ 100 m³/h
B20: ตรวจ: จุดวัด ÷ H | C20: 4–5 เท่า | D20: ='3 ขนาดบ่อ'!$E$15/'3 ขนาดบ่อ'!$E$7 -> 4.5310227 | E20: =IF(AND(D20>=4,D20<=5),"ผ่าน ✔","ไม่ผ่าน ✘") -> ผ่าน ✔
B21: ตรวจ: H ต่ำสุด (น้ำเข้า 50 m³/h) ≥ 0.05 m | C21: ≥ 0.05 | D21: ='2 เวียร์'!$E$10/100 -> 0.14532869 | E21: =IF(D21>=0.05,"ผ่าน ✔","ไม่ผ่าน ✘") -> ผ่าน ✔ | G21: ต่ำกว่านี้วัดไม่แม่น
B23: ข. ช่องท้ายเวียร์ (ม่านน้ำ V-notch ต้องไม่ชนผนัง และน้ำท้ายต้องต่ำ)
B24: ระดับน้ำท้ายเวียร์ (จากพื้น) | C24: ท่อ 8" ที่พื้น: D/2 + (Q ÷ (Cd·A))² ÷ 2g | E24: ='1 ข้อมูล'!$C$36/2+('2 เวียร์'!$D$13/('1 ข้อมูล'!$C$60*PI()*'1 ข้อมูล'!$C$36^2/4))^2/(2*'1 ข้อมูล'!$C$54) -> 0.21068627 | F24: m
B25: ตรวจ: น้ำท้ายต่ำกว่ายอด V ≥ 0.06 m | C25: P − น้ำท้าย | D25: ='3 ขนาดบ่อ'!$E$8-'3 ขนาดบ่อ'!$E$24 -> 0.38931373 | E25: =IF(D25>=0.06,"ผ่าน ✔","ไม่ผ่าน ✘") -> ผ่าน ✔ | G25: ถ้าน้ำท้ายสูงกว่านี้ ค่าที่วัดผิด
B26: ความเร็วผิวบนม่านน้ำ | C26: √(2 g H) | E26: =SQRT(2*'1 ข้อมูล'!$C$54*'3 ขนาดบ่อ'!$E$7) -> 2.0282112 | F26: m/s | G26: ค่าสูงสุด (เผื่อไว้)
B27: ระยะตกของม่านน้ำ | C27: P + H − น้ำท้าย | E27: ='3 ขนาดบ่อ'!$E$8+'3 ขนาดบ่อ'!$E$7-'3 ขนาดบ่อ'!$E$24 -> 0.59897942 | F27: m
B28: ม่านน้ำพุ่งไกล | C28: v × √(2y ÷ g) | E28: ='3 ขนาดบ่อ'!$E$26*SQRT(2*'3 ขนาดบ่อ'!$E$27/'1 ข้อมูล'!$C$54) -> 0.7087607 | F28: m | G28: วิถีโปรเจกไทล์
B29: ความยาวช่องท้ายเวียร์ | C29: ม่านน้ำพุ่งไกล + เผื่อ 0.20 | D29: ='3 ขนาดบ่อ'!$E$28+'1 ข้อมูล'!$C$35 -> 0.9087607 | E29: =CEILING(ROUND(D29,4),'1 ข้อมูล'!$C$13) -> 0.95 | F29: m
B31: ค. โซนรับน้ำตก + ผนังลอดใต้ + สันล้น ช่อง 3 (คสล. หนา 0.10)
B32: ความลึกน้ำช่อง 3 สูงสุด | C32: P + H | E32: ='3 ขนาดบ่อ'!$E$8+'3 ขนาดบ่อ'!$E$7 -> 0.80966569 | F32: m
B33: ความเร็วน้ำแนวราบ ช่อง 3 | C33: Q ÷ (B × ลึก) | E33: ='2 เวียร์'!$D$13/('3 ขนาดบ่อ'!$E$13*'3 ขนาดบ่อ'!$E$32) -> 0.022871808 | F33: m/s
B34: ระยะที่ฟองไหลไปก่อนลอยถึงผิว | C34: (ลึก ÷ v ฟองลอย) × v แนวราบ | E34: ='3 ขนาดบ่อ'!$E$32/'1 ข้อมูล'!$C$33*'3 ขนาดบ่อ'!$E$33 -> 0.18518519 | F34: m
B35: ความยาวโซนรับน้ำตก | C35: MAX(ระยะทำงาน 0.50, ระยะฟอง) | D35: =MAX('1 ข้อมูล'!$C$34,'3 ขนาดบ่อ'!$E$34) -> 0.5 | E35: =CEILING(ROUND(D35,4),'1 ข้อมูล'!$C$13) -> 0.5 | F35: m | G35: ฟองลอยขึ้นผิวน้ำก่อนเข้าช่วงตรง
B36: ① ช่องลอดใต้ผนัง | C36: Q ÷ (B × v ไม่เกิน 0.10) | D36: ='2 เวียร์'!$D$13/('3 ขนาดบ่อ'!$E$13*'1 ข้อมูล'!$C$21) -> 0.18518519 | E36: =CEILING(ROUND(D36,4),'1 ข้อมูล'!$C$13) -> 0.2 | F36: m | G36: ขอบล่างผนังลอดใต้ / ขอบบนเสมอสันกำแพง
B37: ระยะ ① ถึง ② (สันล้น) | C37: เท่าช่องลอด | E37: ='3 ขนาดบ่อ'!$E$36 -> 0.2 | F37: m
B38: ② ความสูงสันล้น | C38: ช่องลอด + 0.10 | D38: ='3 ขนาดบ่อ'!$E$36+'1 ข้อมูล'!$C$27 -> 0.3 | E38: =CEILING(ROUND(D38,4),'1 ข้อมูล'!$C$13) -> 0.3 | F38: m | G38: สันล้น = ต้นช่วงตรง
B39: ระยะรับน้ำตก ก่อนถึง ① | C39: โซนรับน้ำตก − ระยะ ①–② | E39: ='3 ขนาดบ่อ'!$E$35-'3 ขนาดบ่อ'!$E$37 -> 0.3 | F39: m | G39: ตำแหน่ง ① วัดจากสันปลายช่อง 2
B40: ตรวจ: ระยะรับน้ำตก ≥ ระยะฟองลอย | D40: ='3 ขนาดบ่อ'!$E$39-'3 ขนาดบ่อ'!$E$34 -> 0.11481481 | E40: =IF(D40>=0,"ผ่าน ✔","ไม่ผ่าน ✘") -> ผ่าน ✔ | G40: ฟองลอยขึ้นก่อนถึงผนังลอดใต้
B41: ความเร็วข้ามสันล้น (สูงสุด) | C41: Q ÷ (B × (น้ำช่อง 3 − สันล้น)) | E41: ='2 เวียร์'!$D$13/('3 ขนาดบ่อ'!$E$13*('3 ขนาดบ่อ'!$E$32-'3 ขนาดบ่อ'!$E$38)) -> 0.036334638 | F41: m/s
B42: ตรวจ: ความเร็วข้ามสันล้น ≤ 0.10 | D42: ='3 ขนาดบ่อ'!$E$41 -> 0.036334638 | E42: =IF(D42<=0.1,"ผ่าน ✔","ไม่ผ่าน ✘") -> ผ่าน ✔
B43: ตรวจ: น้ำเหนือสันล้น ที่น้ำเข้าต่ำสุด | C43: ≥ 0.10 m | D43: ='3 ขนาดบ่อ'!$E$8+'2 เวียร์'!$E$10/100-'3 ขนาดบ่อ'!$E$38 -> 0.44532869 | E43: =IF(D43>=0.1,"ผ่าน ✔","ไม่ผ่าน ✘") -> ผ่าน ✔
B45: ง. ช่อง 2 โชว์น้ำใส
...

Sheet 4 ช่องโชว์น้ำ
B1: 4) ช่อง 2 โชว์น้ำใส — ชั้นน้ำบนพื้นยกหนาเท่าไร
B2: สันปลาย: Q = 1.84 × B × H^1.5 → H = (Q ÷ (1.84 × B))^(2/3) | ความลึก = สันปลาย + H | Froude = v ÷ √(g × ลึก) (< 0.5 = ผิวน้ำเรียบ)
B4: กรณี | C4: Q ผ่านช่อง 2 (m³/h) | D4: Q (m³/s) | E4: ม่านน้ำบนสัน H (cm) | F4: ชั้นน้ำบนพื้นยก (cm) = สัน + H | G4: ความเร็ว v (m/s) = Q ÷ (B × ลึก) | H4: Froude | I4: ผิวน้ำ
B5: น้ำเข้าต่ำสุด ปั๊มเดิน | C5: ='1 ข้อมูล'!$C$7-'1 ข้อมูล'!$C$9 -> 40 | D5: =C5/3600 -> 0.011111111 | E5: =(D5/('1 ข้อมูล'!$C$59*'3 ขนาดบ่อ'!$E$13))^(2/3)*100 -> 2.5306511 | F5: ='1 ข้อมูล'!$C$17*100+E5 -> 4.5306511 | G5: =D5/('3 ขนาดบ่อ'!$E$13*F5/100) -> 0.16349543 | H5: =G5/SQRT('1 ข้อมูล'!$C$54*F5/100) -> 0.24523971 | I5: =IF(H5<0.5,"เรียบ ✔",IF(H5<0.7,"พอใช้","เป็นระลอก ✘")) -> เรียบ ✔
B6: น้ำเข้าเฉลี่ย ปั๊มเดิน | C6: ='1 ข้อมูล'!$C$10-'1 ข้อมูล'!$C$9 -> 52.791667 | D6: =C6/3600 -> 0.014664352 | E6: =(D6/('1 ข้อมูล'!$C$59*'3 ขนาดบ่อ'!$E$13))^(2/3)*100 -> 3.0448731 | F6: ='1 ข้อมูล'!$C$17*100+E6 -> 5.0448731 | G6: =D6/('3 ขนาดบ่อ'!$E$13*F6/100) -> 0.19378554 | H6: =G6/SQRT('1 ข้อมูล'!$C$54*F6/100) -> 0.27546203 | I6: =IF(H6<0.5,"เรียบ ✔",IF(H6<0.7,"พอใช้","เป็นระลอก ✘")) -> เรียบ ✔
B7: น้ำเข้าสูงสุด ปั๊มเดิน | C7: ='1 ข้อมูล'!$C$8-'1 ข้อมูล'!$C$9 -> 90 | D7: =C7/3600 -> 0.025 | E7: =(D7/('1 ข้อมูล'!$C$59*'3 ขนาดบ่อ'!$E$13))^(2/3)*100 -> 4.3453085 | F7: ='1 ข้อมูล'!$C$17*100+E7 -> 6.3453085 | G7: =D7/('3 ขนาดบ่อ'!$E$13*F7/100) -> 0.26266125 | H7: =G7/SQRT('1 ข้อมูล'!$C$54*F7/100) -> 0.33291635 | I7: =IF(H7<0.5,"เรียบ ✔",IF(H7<0.7,"พอใช้","เป็นระลอก ✘")) -> เรียบ ✔
B8: น้ำเข้าสูงสุด ปั๊มหยุด | C8: ='1 ข้อมูล'!$C$8 -> 100 | D8: =C8/3600 -> 0.027777778 | E8: =(D8/('1 ข้อมูล'!$C$59*'3 ขนาดบ่อ'!$E$13))^(2/3)*100 -> 4.6614992 | F8: ='1 ข้อมูล'!$C$17*100+E8 -> 6.6614992 | G8: =D8/('3 ขนาดบ่อ'!$E$13*F8/100) -> 0.27799326 | H8: =G8/SQRT('1 ข้อมูล'!$C$54*F8/100) -> 0.34388542 | I8: =IF(H8<0.5,"เรียบ ✔",IF(H8<0.7,"พอใช้","เป็นระลอก ✘")) -> เรียบ ✔
B10: • ชั้นน้ำบนพื้นยก = ความหนาน้ำที่คนจะมองเห็น (ช่องสีเขียว)
B11: • Froude < 0.5 ผิวน้ำเรียบเหมือนกระจก เห็นพื้นชัด / 0.7–1.3 ผิวน้ำเป็นระลอก ดูไม่ใส
B12: • อยากให้น้ำบางลง: ลดสันปลาย (ชีต 1) — แต่ Froude จะสูงขึ้น ให้ดูคอลัมน์ 'ผิวน้ำ' ประกอบ

Sheet 5 ระดับ
B1: 5) ระดับต่าง ๆ ของบ่อ (พื้นบ่อ = ±0.000 m)
B2: ที่น้ำเข้าสูงสุด ปั๊มหยุด (น้ำสูงที่สุด) — ทุกค่าดึงจากชีต 3
B4: ระดับ | C4: m | D4: คิดจาก
B5: สันกำแพง | C5: ='3 ขนาดบ่อ'!$E$70 -> 1.2 | D5: น้ำช่อง 1 + freeboard
B6: น้ำ ช่อง 1 | C6: ='3 ขนาดบ่อ'!$E$67 -> 0.97252327 | D6: พื้นยก + ชั้นน้ำ + การสูญเสีย
B7: สันปลาย ช่อง 2 | C7: ='3 ขนาดบ่อ'!$E$47+'1 ข้อมูล'!$C$17 -> 0.92 | D7: พื้นยก + สันปลาย
B8: ผิวพื้นยก ช่อง 2 | C8: ='3 ขนาดบ่อ'!$E$47 -> 0.9 | D8: น้ำช่อง 3 + 0.10 − สันปลาย
B9: ขอบบนแผ่นเวียร์ | C9: ='3 ขนาดบ่อ'!$E$76 -> 1 | D9: P + ลึกร่อง + 0.10
B10: ขอบบนร่อง V | C10: ='3 ขนาดบ่อ'!$E$8+'3 ขนาดบ่อ'!$E$9 -> 0.9 | D10: P + ลึกร่อง
B11: น้ำ ช่อง 3 สูงสุด | C11: ='3 ขนาดบ่อ'!$E$32 -> 0.80966569 | D11: P + Hmax
B12: ยอด V (H = 0) | C12: ='3 ขนาดบ่อ'!$E$8 -> 0.6 | D12: P
B13: สันกำแพงเวียร์ คสล. | C13: ='3 ขนาดบ่อ'!$E$73 -> 0.5 | D13: P − 0.10
B14: ขอบล่างแผ่นเวียร์ | C14: ='3 ขนาดบ่อ'!$E$75 -> 0.4 | D14: สันกำแพงเวียร์ − 0.10
B15: ขอบล่างผนังกั้น ช่อง 1 | C15: ='1 ข้อมูล'!$C$29+'3 ขนาดบ่อ'!$E$53 -> -0.7 | D15: พื้นช่อง 1 + ช่องลอด
B16: น้ำท้ายเวียร์ | C16: ='3 ขนาดบ่อ'!$E$24 -> 0.21068627 | D16: ท่อออก 8"
B17: ปั๊ม STOP ช่อง 1 | C17: ='1 ข้อมูล'!$C$29+0.6 -> -0.4 | D17: พื้นช่อง 1 + 0.60
B18: ปลายท่อจุ่ม | C18: ='1 ข้อมูล'!$C$29+0.5 -> -0.5 | D18: พื้นช่อง 1 + 0.50
B19: พื้นบ่อ ช่อง 2–3 | C19: =0 -> 0
B20: พื้นช่อง 1 | C20: ='1 ข้อมูล'!$C$29 -> -1 | D20: ทางเลือก A

Sheet 6 ตาราง H-Q
B1: 6) ตาราง H → Q สำหรับอ่านค่าหน้างาน
B2: วัด H จากยอด V (cm) แล้วอ่าน Q | กรมฯ: Q = 1.38 × H^2.5 | ISO: Q = K × (H + kh)^2.5
B4: H (cm) | C4: Q กรมฯ (m³/h) | D4: Q ISO (m³/h) | E4: ต่างกัน (%) | F4: Q กรมฯ (L/s) | G4: Q กรมฯ (m³/วัน)
B5: 5 | C5: ='2 เวียร์'!$C$5*(B5/100)^2.5*3600 -> 2.7771964 | D5: ='2 เวียร์'!$C$6*(B5/100+'1 ข้อมูล'!$C$58)^2.5*3600 -> 2.8661965 | E5: =C5/D5-1 -> -0.031051631 | F5: =C5/3.6 -> 0.77144345 | G5: =C5*24 -> 66.652714
B6: 6 | C6: ='2 เวียร์'!$C$5*(B6/100)^2.5*3600 -> 4.3808634 | D6: ='2 เวียร์'!$C$6*(B6/100+'1 ข้อมูล'!$C$58)^2.5*3600 -> 4.4898313 | E6: =C6/D6-1 -> -0.024269933 | F6: =C6/3.6 -> 1.2169065 | G6: =C6*24 -> 105.14072
B7: 7 | C7: ='2 เวียร์'!$C$5*(B7/100)^2.5*3600 -> 6.4406053 | D7: ='2 เวียร์'!$C$6*(B7/100+'1 ข้อมูล'!$C$58)^2.5*3600 -> 6.5679253 | E7: =C7/D7-1 -> -0.019385113 | F7: =C7/3.6 -> 1.789057 | G7: =C7*24 -> 154.57453
B8: 8 | C8: ='2 เวียร์'!$C$5*(B8/100)^2.5*3600 -> 8.9930406 | D8: ='2 เวียร์'!$C$6*(B8/100+'1 ข้อมูล'!$C$58)^2.5*3600 -> 9.1364741 | E8: =C8/D8-1 -> -0.015699002 | F8: =C8/3.6 -> 2.4980668 | G8: =C8*24 -> 215.83297
B9: 9 | C9: ='2 เวียร์'!$C$5*(B9/100)^2.5*3600 -> 12.07224 | D9: ='2 เวียร์'!$C$6*(B9/100+'1 ข้อมูล'!$C$58)^2.5*3600 -> 12.228999 | E9: =C9/D9-1 -> -0.012818602 | F9: =C9/3.6 -> 3.3534 | G9: =C9*24 -> 289.73376
B10: 10 | C10: ='2 เวียร์'!$C$5*(B10/100)^2.5*3600 -> 15.710195 | D10: ='2 เวียร์'!$C$6*(B10/100+'1 ข้อมูล'!$C$58)^2.5*3600 -> 15.876996 | E10: =C10/D10-1 -> -0.010505779 | F10: =C10/3.6 -> 4.3639432 | G10: =C10*24 -> 377.04469
B11: 11 | C11: ='2 เวียร์'!$C$5*(B11/100)^2.5*3600 -> 19.93716 | D11: ='2 เวียร์'!$C$6*(B11/100+'1 ข้อมูล'!$C$58)^2.5*3600 -> 20.110266 | E11: =C11/D11-1 -> -0.0086078226 | F11: =C11/3.6 -> 5.5381001 | G11: =C11*24 -> 478.49185
B12: 12 | C12: ='2 เวียร์'!$C$5*(B12/100)^2.5*3600 -> 24.781906 | D12: ='2 เวียร์'!$C$6*(B12/100+'1 ข้อมูล'!$C$58)^2.5*3600 -> 24.957162 | E12: =C12/D12-1 -> -0.0070222967 | F12: =C12/3.6 -> 6.8838627 | G12: =C12*24 -> 594.76574
B13: 13 | C13: ='2 เวียร์'!$C$5*(B13/100)^2.5*3600 -> 30.27192 | D13: ='2 เวียร์'!$C$6*(B13/100+'1 ข้อมูล'!$C$58)^2.5*3600 -> 30.444783 | E13: =C13/D13-1 -> -0.0056779238 | F13: =C13/3.6 -> 8.4088667 | G13: =C13*24 -> 726.52608
B14: 14 | C14: ='2 เวียร์'!$C$5*(B14/100)^2.5*3600 -> 36.433566 | D14: ='2 เวียร์'!$C$6*(B14/100+'1 ข้อมูล'!$C$58)^2.5*3600 -> 36.599125 | E14: =C14/D14-1 -> -0.0045235751 | F14: =C14/3.6 -> 10.120435 | G14: =C14*24 -> 874.40558
B15: 15 | C15: ='2 เวียร์'!$C$5*(B15/100)^2.5*3600 -> 43.292208 | D15: ='2 เวียร์'!$C$6*(B15/100+'1 ข้อมูล'!$C$58)^2.5*3600 -> 43.445205 | E15: =C15/D15-1 -> -0.0035216214 | F15: =C15/3.6 -> 12.025613 | G15: =C15*24 -> 1039.013
B16: 16 | C16: ='2 เวียร์'!$C$5*(B16/100)^2.5*3600 -> 50.87232 | D16: ='2 เวียร์'!$C$6*(B16/100+'1 ข้อมูล'!$C$58)^2.5*3600 -> 51.00717 | E16: =C16/D16-1 -> -0.0026437534 | F16: =C16/3.6 -> 14.1312 | G16: =C16*24 -> 1220.9357
... B25: 25 | C25: ='2 เวียร์'!$C$5*(B25/100)^2.5*3600 -> 155.25 | D25: ='2 เวียร์'!$C$6*(B25/100+'1 ข้อมูล'!$C$58)^2.5*3600 -> 154.92226 | E25: =C25/D25-1 -> 0.0021154937 | F25: =C25/3.6 -> 43.125 | G25: =C25*24 -> 3726

Sheet 7 แบบพับ
B1: 7) แบบพับบ่อเป็น 2 แถว (U / L) เทียบกับแบบตรง
B2: แถว 1: ช่อง 1 → ช่อง 2 (พื้นยก) | น้ำล้นข้ามสันด้านข้างลงแถว 2 | แถว 2: รับน้ำตก → ช่วงตรง → เวียร์ → ท่อออก (ไหลย้อนกลับ)
B4: รายการ | C4: วิธีคิด | D4: ค่า | E4: หน่วย | F4: หมายเหตุ
B6: ก. ความยาวแต่ละแถว (ใช้ขนาดจากชีต 3)
B7: แถว 1: ช่อง 1 | C7: โซนน้ำเข้า + ผนังกั้น + โซนปั๊ม | D7: ='3 ขนาดบ่อ'!$E$62 -> 3.25 | E7: m
B8: แถว 1: ช่อง 2 (พื้นยก) | C8: ความยาวช่อง 2 = ความยาวสันข้าง | D8: ='3 ขนาดบ่อ'!$E$49 -> 1 | E8: m | F8: น้ำไหลขวางบ่อ แล้วล้นสันลงแถว 2
B9: แถว 1: รวม | C9: ช่อง 1 + ช่อง 2 | D9: ='7 แบบพับ'!$D$7+'7 แบบพับ'!$D$8 -> 4.25 | E9: m
B10: แถว 2: โซนรับน้ำตก | C10: MAX(ความยาวสัน, โซนรับน้ำตกขั้นต่ำ) | D10: =MAX('7 แบบพับ'!$D$8,'3 ขนาดบ่อ'!$E$35) -> 1 | E10: m | F10: ม่านน้ำตกตลอดความยาวสัน
B11: แถว 2: รวม | C11: รับน้ำตก + ช่วงตรง + กำแพงเวียร์ + ท้ายเวียร์ | D11: ='7 แบบพับ'!$D$10+'3 ขนาดบ่อ'!$E$14+'1 ข้อมูล'!$C$49+'3 ขนาดบ่อ'!$E$29 -> 4.25 | E11: m
B12: ความยาวภายในบ่อ | C12: MAX(แถว 1, แถว 2) | D12: =MAX('7 แบบพับ'!$D$9,'7 แบบพับ'!$D$11) -> 4.25 | E12: m
B13: พื้นที่ว่างท้ายแถว 1 | C13: ความยาวภายใน − แถว 1 | D13: ='7 แบบพับ'!$D$12-'7 แบบพับ'!$D$9 -> 0 | E13: m | F13: แบบ L: ตัดส่วนนี้ทิ้ง / แบบ U: ใช้เป็นที่ตั้งตู้คอนโทรล
B14: ความกว้างภายใน | C14: B + ผนังกลาง + B | D14: =2*'3 ขนาดบ่อ'!$E$13+'1 ข้อมูล'!$C$49 -> 3.2 | E14: m
B16: ข. เทียบ 3 แบบ (ขนาดภายนอก)
C17: แบบตรง (ปัจจุบัน) | D17: แบบ U (สี่เหลี่ยม) | E17: แบบ L (ตัดมุมว่าง)
B18: ยาว (m) | C18: ='3 ขนาดบ่อ'!$E$114 -> 8.6 | D18: ='7 แบบพับ'!$D$12+2*'1 ข้อมูล'!$C$49 -> 4.65 | E18: ='7 แบบพับ'!$D$12+2*'1 ข้อมูล'!$C$49 -> 4.65
B19: กว้าง (m) | C19: ='3 ขนาดบ่อ'!$E$115 -> 1.9 | D19: ='7 แบบพับ'!$D$14+2*'1 ข้อมูล'!$C$49 -> 3.6 | E19: ='7 แบบพับ'!$D$14+2*'1 ข้อมูล'!$C$49 -> 3.6
B20: พื้นที่ฐาน (m²) | C20: ='3 ขนาดบ่อ'!$E$114*'3 ขนาดบ่อ'!$E$115 -> 16.34 | D20: =('7 แบบพับ'!$D$12+2*'1 ข้อมูล'!$C$49)*('7 แบบพับ'!$D$14+2*'1 ข้อมูล'!$C$49) -> 16.74 | E20: =('7 แบบพับ'!$D$9+2*'1 ข้อมูล'!$C$49)*('7 แบบพับ'!$D$14+2*'1 ข้อมูล'!$C$49)+('7 แบบพับ'!$D$12-'7 แบบพับ'!$D$9)*('3 ขนาดบ่อ'!$E$13+2*'1 ข้อมูล'!$C$49) -> 16.74
B21: ผนังรอบนอก (m³) | C21: =2*('3 ขนาดบ่อ'!$E$110+'1 ข้อมูล'!$C$49+'3 ขนาดบ่อ'!$E$111+'1 ข้อมูล'!$C$49)*'1 ข้อมูล'!$C$49*'3 ขนาดบ่อ'!$E$70 -> 4.848 | D21: =2*('7 แบบพับ'!$D$12+'1 ข้อมูล'!$C$49+'7 แบบพับ'!$D$14+'1 ข้อมูล'!$C$49)*'1 ข้อมูล'!$C$49*'3 ขนาดบ่อ'!$E$70 -> 3.768 | E21: =2*('7 แบบพับ'!$D$12+'1 ข้อมูล'!$C$49+'7 แบบพับ'!$D$14+'1 ข้อมูล'!$C$49)*'1 ข้อมูล'!$C$49*'3 ขนาดบ่อ'!$E$70 -> 3.768
B22: ผนังกลาง (m³) | C22: =0 -> 0 | D22: =('7 แบบพับ'!$D$12-'7 แบบพับ'!$D$8)*'1 ข้อมูล'!$C$49*'3 ขนาดบ่อ'!$E$70 -> 0.78 | E22: ='7 แบบพับ'!$D$7*'1 ข้อมูล'!$C$49*'3 ขนาดบ่อ'!$E$70 -> 0.78
B23: พื้น (m³) | C23: ='3 ขนาดบ่อ'!$E$114*'3 ขนาดบ่อ'!$E$115*'1 ข้อมูล'!$C$50 -> 3.268 | D23: =('7 แบบพับ'!$D$12+2*'1 ข้อมูล'!$C$49)*('7 แบบพับ'!$D$14+2*'1 ข้อมูล'!$C$49)*'1 ข้อมูล'!$C$50 -> 3.348 | E23: =(('7 แบบพับ'!$D$9+2*'1 ข้อมูล'!$C$49)*('7 แบบพับ'!$D$14+2*'1 ข้อมูล'!$C$49)+('7 แบบพับ'!$D$12-'7 แบบพับ'!$D$9)*('3 ขนาดบ่อ'!$E$13+2*'1 ข้อมูล'!$C$49))*'1 ข้อมูล'!$C$50 -> 3.348
B24: คอนกรีตรวม (m³) โดยประมาณ | C24: =SUM(C21:C23) -> 8.116 | D24: =SUM(D21:D23) -> 7.896 | E24: =SUM(E21:E23) -> 7.896 | F24: ไม่รวมพื้นยก กำแพงเวียร์ ผนังกั้น (เท่ากันทุกแบบ)
B25: ยาวลดลงจากแบบตรง | C25: - | D25: =1-D18/C18 -> 0.45930233 | E25: =1-E18/C18 -> 0.45930233
B28: ค. ได้อะไร / เสียอะไร
B29: ✔ สั้นลง | C29: บ่อยาวลดลงประมาณ 30% วางในพื้นที่จำกัดได้ง่าย
B30: ✔ ท่อเข้า–ออกอยู่ด้านเดียวกัน | C30: ท่อเข้า 6" (แถว 1) และท่อออก 8" (แถว 2) อยู่ฝั่งเดียวกัน เดินท่อสั้นลง
B31: ✔ จุดโชว์รวมกัน | C31: ช่อง 2 (น้ำใส) อยู่ติด BOD probe และ Flow meter ยืนดูจุดเดียวเห็นครบ
B32: ✔ คอนกรีตแบบ L ใกล้เคียงแบบตรง | C32: แบบ U ใช้คอนกรีตมากกว่า เพราะมีมุมว่าง
B33: ✘ น้ำต้องเลี้ยว 2 ครั้ง | C33: บนพื้นยก (เลี้ยว 90°) และตอนตกลงแถว 2 (ไหลจากด้านข้างแล้วเลี้ยวไปตามแถว)
B34: ✘ ผิวน้ำช่อง 2 อาจไม่เรียบเท่าแบบตรง | C34: น้ำขึ้นพื้นยกจากด้านหนึ่ง แล้วไหลออกอีกด้าน มุมพื้นยกจะมีน้ำนิ่งหรือวน
B35: ✘ ความเสี่ยงค่า Flow แกว่ง | C35: น้ำเข้าแถว 2 จากด้านข้าง กระแสช่วงต้นไม่สม่ำเสมอ ช่วงตรง 2.10 m ช่วยได้ ถ้ายังแกว่งให้ใส่ผนังลอดใต้ต้นช่วงตรง
B36: ✘ แบบหล่อซับซ้อนขึ้น | C36: มีผนังกลางและมุมเพิ่ม ค่าแรงไม้แบบเพิ่ม

Sheet 8 เทียบวิธี มข.
B1: 8) ออกแบบตามวิธีในเอกสาร มข. (EN614102 Ex 3.9) เทียบกับแบบของเรา
B2: สมการ USBR: Q = 1.36 H^2.48 | เกณฑ์: P ≥ 2Hmax, b ≥ 2Hmax (b = ระยะจากขอบบนร่อง V ถึงผนัง), จุดวัด 3–5 Hmax
B4: No. | C4: Parameters | D4: Symbol | E4: Unit | F4: Value (วิธี มข.) | G4: Remark (ตามเอกสาร) | H4: แบบของเรา (ชีต 3) | I4: แบบเราผ่านเกณฑ์ มข.?
B5: 1 | C5: Average flow rate | D5: Qavg | E5: m³/s | F5: ='1 ข้อมูล'!$C$10/3600 -> 0.01744213 | G5: 1,507 m³/วัน ÷ 24 ÷ 3600
B6: 2 | C6: Peak flow rate | D6: Qpeak | E6: m³/s | F6: =1.5*F5 -> 0.026163194 | G6: *Calculated from 1.5 of average
B7: 2a | C7: Peak flow (ใบเสนอราคา) | D7: Qmax | E7: m³/s | F7: ='1 ข้อมูล'!$C$8/3600 -> 0.027777778 | G7: 100 m³/h ตามใบเสนอราคา
B8: 3 | C8: Number of Weir Channel | D8: n | F8: 1 | G8: *Design | H8: 1
B9: 4 | C9: Flow rate at Hmax of each weir | D9: QHmax | E9: m³/s | F9: =MAX(F6,F7)/F8 -> 0.027777778 | G9: *MAX(Qpeak, ใบเสนอราคา) / n | H9: ='2 เวียร์'!$D$13 -> 0.027777778
B10: 5 | C10: b | E10: m | F10: =F12*2*1.1 -> 0.45817883 | G10: *Calculate from Hmax*2*1.1 | H10: =('3 ขนาดบ่อ'!$E$13-'3 ขนาดบ่อ'!$E$10)/2 -> 0.45 | I10: =IF(H10>=2*F12,"ผ่าน ✔","ไม่ผ่าน ✘ (ต้อง ≥ 2Hmax)") -> ผ่าน ✔
B11: 6 | C11: P | E11: m | F11: =F12*2 -> 0.41652621 | G11: *Calculate from Hmax*2 | H11: ='3 ขนาดบ่อ'!$E$8 -> 0.6 | I11: =IF(H11>=2*F12,"ผ่าน ✔","ไม่ผ่าน ✘") -> ผ่าน ✔
B12: 7 | C12: Hmax | E12: m | F12: =(F9/1.36)^(1/2.48) -> 0.2082631 | G12: *Calculated from Q=1.36Hmax^2.48 | H12: ='3 ขนาดบ่อ'!$E$7 -> 0.20966569 | I12: เราใช้สูตรกรมฯ 1.38H^2.5
B13: 8 | C13: P/2 | F13: =F11/2 -> 0.2082631 | G13: ="Check P/2 ≥ Hmax: "&IF(F13>=F12,"✔","✘") -> Check P/2 ≥ Hmax: ✔
B14: 9 | C14: b/2 | F14: =F10/2 -> 0.22908941 | G14: ="Check b/2 ≥ Hmax: "&IF(F14>=F12,"✔","✘") -> Check b/2 ≥ Hmax: ✔
B15: 10 | C15: Point of measurement H | E15: m | F15: =F12*3 -> 0.62478931 | G15: *Calculate from Hmax*3 (เอกสารยอมให้ 3–5 Hmax) | H15: ='3 ขนาดบ่อ'!$E$15 -> 0.95 | I15: =IF(AND(H15>=3*F12,H15<=5*F12),"ผ่าน ✔ (อยู่ใน 3–5 Hmax)","ไม่ผ่าน ✘") -> ผ่าน ✔ (อยู่ใน 3–5 Hmax)
B16: 11 | C16: H of V-Notch | E16: m | F16: =F12*1.2 -> 0.24991572 | G16: *Calculate from Hmax*1.2 | H16: ='3 ขนาดบ่อ'!$E$9 -> 0.3 | I16: =IF(H16>=1.2*F12,"ผ่าน ✔","ไม่ผ่าน ✘") -> ผ่าน ✔
B17: 12 | C17: B | E17: m | F17: =F10*2+2*F16/TAN(RADIANS(45)) -> 1.4161891 | G17: *Calculate from b*2+[2*H of V Notch]/tan45 | H17: ='3 ขนาดบ่อ'!$E$13 -> 1.5 | I17: =IF(H17>=F17,"ผ่าน ✔","แคบกว่า ✘") -> ผ่าน ✔
B19: หมายเหตุ
B20: • สไลด์ตัวอย่าง (Q = 0.75 m³/s) ได้ B = 4.63 เพราะ Excel ใช้ TAN(45) ซึ่งตีความ 45 เป็นเรเดียน (tan = 1.62) — ค่าที่ถูกคือ TAN(RADIANS(45)) = 1 → B = 5.34
B21: • b ในเอกสาร = ระยะจากขอบบนร่อง V ถึงผนังข้างละด้าน (เกณฑ์ USBR: ≥ 2Hmax) — แบบของเราใช้เกณฑ์ ISO 1438 (B ≥ 5Hmax) จึงแคบกว่า
B22: • สูตร USBR 1.36H^2.48 ให้ Q สูงกว่าสูตรกรมฯ 1.38H^2.5 ประมาณ 2% ในช่วง H 0.15–0.21 m

Sheet 9 HRT ช่อง 1
B1: 9) ระยะเวลากักน้ำ (HRT) ช่อง 1 — เป้าหมาย 15 นาที
B2: HRT = ปริมาตรน้ำช่อง 1 ÷ น้ำเข้า | ระดับน้ำช่อง 1 ถูกพื้นยกช่อง 2 กำหนด จึงเพิ่มปริมาตรด้วยการลดพื้นช่อง 1 และขยายขนาด
B4: ข้อมูล | C4: ค่า | D4: หน่วย | G4: หมายเหตุ
B5: HRT ที่ต้องการ | C5: ='1 ข้อมูล'!$C$28 -> 15 | D5: นาที | G5: จากชีต 1
B6: น้ำเข้าที่ใช้คิด HRT | C6: ='1 ข้อมูล'!$C$10 -> 62.791667 | D6: m³/h | G6: ค่าเฉลี่ย (แก้เป็น 100 ได้ถ้าคิดที่ค่าสูงสุด)
B7: ปริมาตรปั๊มจุ่ม + ท่อจุ่ม (หัก) | C7: 0.09 | D7: m³ | G7: ปั๊ม 0.40 × 0.40 × 0.55
B8: ระดับน้ำช่อง 1 (ที่ Q นี้) | C8: ='3 ขนาดบ่อ'!$E$47+'4 ช่องโชว์น้ำ'!$F$6/100+1.5*'4 ช่องโชว์น้ำ'!$G$6^2/(2*'1 ข้อมูล'!$C$54) -> 0.95331974 | D8: m | G8: พื้นยก + ชั้นน้ำ + การสูญเสีย (ที่ Qavg)
B9: ปริมาตรน้ำที่ต้องการ | C9: =C6*C5/60+C7 -> 15.787917 | D9: m³ | G9: Q × HRT + ส่วนที่ปั๊มกินที่
B10: HRT แบบเดิม (ช่อง 1 ยาว 1.60 พื้น ±0) | C10: =('3 ขนาดบ่อ'!$E$62*'3 ขนาดบ่อ'!$E$13*C8-C7)/C6*60 -> 4.3548139 | D10: นาที | G10: ก่อนแก้
B12: ทางเลือก
B13: รายการ | C13: ทางเลือก A (ใช้) | D13: ทางเลือก B | E13: หน่วย | G13: วิธีคิด
B14: ระดับพื้นช่อง 1 | C14: ='1 ข้อมูล'!$C$29 -> -1 | D14: -1.5 | E14: m | G14: A = ค่าที่ใช้ (ชีต 1) / B = เทียบ
B15: ความกว้างช่อง 1 | C15: ='1 ข้อมูล'!$C$30 -> 2.5 | D15: ='3 ขนาดบ่อ'!$E$13 -> 1.5 | E15: m | G15: A = ค่าที่ใช้ (ชีต 1) / B = กว้างเท่าบ่อ
B16: น้ำลึก | C16: =$C$8-C14 -> 1.9533197 | D16: =$C$8-D14 -> 2.4533197 | E16: m | G16: ระดับน้ำ − พื้น
B17: ความยาวช่อง 1 ขั้นต่ำ | C17: =$C$9/(C15*C16) -> 3.233043 | D17: =$C$9/(D15*D16) -> 4.2902185 | E17: m | G17: ปริมาตร ÷ (กว้าง × ลึก)
B18: ความยาวช่อง 1 ที่ใช้ | C18: =CEILING(ROUND(C17,4),'1 ข้อมูล'!$C$13) -> 3.25 | D18: =CEILING(ROUND(D17,4),'1 ข้อมูล'!$C$13) -> 4.3 | E18: m | G18: ปัดขึ้นทีละ 0.05
B19: ปริมาตรน้ำจริง | C19: =C18*C15*C16-$C$7 -> 15.780723 | D19: =D18*D15*D16-$C$7 -> 15.733912 | E19: m³
B20: HRT ที่ได้ | C20: =C19/$C$6*60 -> 15.079125 | D20: =D19/$C$6*60 -> 15.034395 | E20: นาที
B21: ตรวจ HRT | C21: =IF(C20>=$C$5,"ผ่าน ✔","ไม่ผ่าน ✘") -> ผ่าน ✔ | D21: =IF(D20>=$C$5,"ผ่าน ✔","ไม่ผ่าน ✘") -> ผ่าน ✔
B22: HRT ที่น้ำเข้าสูงสุด | C22: =C19/'1 ข้อมูล'!$C$8*60 -> 9.4684337 | D22: =D19/'1 ข้อมูล'!$C$8*60 -> 9.4403474 | E22: นาที | G22: ข้อมูลประกอบ
B23: ปั๊ม recycle เดินต่อได้เมื่อน้ำเข้าหยุด | C23: =C18*C15*($C$8-(C14+0.6))/'1 ข้อมูล'!$C$9*60 -> 65.974337 | D23: =D18*D15*($C$8-(D14+0.6))/'1 ข้อมูล'!$C$9*60 -> 71.723474 | E23: นาที | G23: จากระดับน้ำลงถึง STOP (พื้น + 0.60)
B24: ความสูงผนังช่อง 1 (จากพื้นช่อง 1) | C24: ='3 ขนาดบ่อ'!$E$70-C14 -> 2.2 | D24: ='3 ขนาดบ่อ'!$E$70-D14 -> 2.7 | E24: m | G24: สันกำแพง − พื้น
B25: บ่อยาวภายนอก | C25: =C18+'3 ขนาดบ่อ'!$E$49+'3 ขนาดบ่อ'!$E$109+2*'1 ข้อมูล'!$C$49 -> 8.6 | D25: =D18+'3 ขนาดบ่อ'!$E$49+'3 ขนาดบ่อ'!$E$109+2*'1 ข้อมูล'!$C$49 -> 9.65 | E25: m | G25: ช่อง 1 + ช่อง 2 + ช่อง 3 + ผนัง
B26: กว้างภายนอก (ช่อง 1 / ช่อง 2–3) | C26: =TEXT(C15+2*'1 ข้อมูล'!$C$49,"0.00")&" / "&TEXT('3 ขนาดบ่อ'!$E$13+2*'1 ข้อมูล'!$C$49,"0.00") -> 2.90 / 1.90 | D26: =TEXT(D15+2*'1 ข้อมูล'!$C$49,"0.00")&" / "&TEXT('3 ขนาดบ่อ'!$E$13+2*'1 ข้อมูล'!$C$49,"0.00") -> 1.90 / 1.90 | E26: m
B28: ตารางเลือกขนาด: ความยาวช่อง 1 ที่ต้องใช้ (m)
B29: พื้นช่อง 1 \ กว้าง (m) | C29: 1.5 | D29: 2 | E29: 2.5 | F29: 3 | G29: น้ำลึก (m)
B30: 0 | C30: =$C$9/(C$29*($C$8-$B30)) -> 11.040659 | D30: =$C$9/(D$29*($C$8-$B30)) -> 8.2804939 | E30: =$C$9/(E$29*($C$8-$B30)) -> 6.6243951 | F30: =$C$9/(F$29*($C$8-$B30)) -> 5.5203293 | G30: =$C$8-B30 -> 0.95331974
B31: -0.5 | C31: =$C$9/(C$29*($C$8-$B31)) -> 7.2422313 | D31: =$C$9/(D$29*($C$8-$B31)) -> 5.4316735 | E31: =$C$9/(E$29*($C$8-$B31)) -> 4.3453388 | F31: =$C$9/(F$29*($C$8-$B31)) -> 3.6211157 | G31: =$C$8-B31 -> 1.4533197
B32: -1 | C32: =$C$9/(C$29*($C$8-$B32)) -> 5.388405 | D32: =$C$9/(D$29*($C$8-$B32)) -> 4.0413037 | E32: =$C$9/(E$29*($C$8-$B32)) -> 3.233043 | F32: =$C$9/(F$29*($C$8-$B32)) -> 2.6942025 | G32: =$C$8-B32 -> 1.9533197
B33: -1.5 | C33: =$C$9/(C$29*($C$8-$B33)) -> 4.2902185 | D33: =$C$9/(D$29*($C$8-$B33)) -> 3.2176639 | E33: =$C$9/(E$29*($C$8-$B33)) -> 2.5741311 | F33: =$C$9/(F$29*($C$8-$B33)) -> 2.1451093 | G33: =$C$8-B33 -> 2.4533197
B34: -2 | C34: =$C$9/(C$29*($C$8-$B34)) -> 3.5638802 | D34: =$C$9/(D$29*($C$8-$B34)) -> 2.6729102 | E34: =$C$9/(E$29*($C$8-$B34)) -> 2.1383281 | F34: =$C$9/(F$29*($C$8-$B34)) -> 1.7819401 | G34: =$C$8-B34 -> 2.9533197
B36: • ระดับน้ำช่อง 1 ถูกพื้นยกช่อง 2 กำหนดไว้ (~+0.95) จึงเพิ่มปริมาตรได้ทางเดียวคือขุดพื้นช่อง 1 ให้ลึกขึ้นหรือขยายขนาด
B37: • HRT นานขึ้น ตะกอนจะตกที่พื้นช่อง 1 มากขึ้น — ทำพื้นลาดเข้าหาปั๊ม 1:10 และเตรียมทางดูดตะกอน
B38: • ผนังช่อง 1 ที่ลึกขึ้นรับแรงดันดิน/น้ำมากขึ้น — ให้วิศวกรโยธาตรวจความหนาและเหล็กเสริม
